[2024-05-17T19:12:49.007+0000] {task_context_logger.py:104} ERROR - Executor reports task instance <TaskInstance: process_sales.convert_to_avro scheduled__2022-08-19T01:00:00+00:00 [queued]> finished (failed) although the task says it's queued. (Info: None) Was the task killed externally?
