[2024-05-17T15:21:24.566+0000] {local_task_job_runner.py:120} INFO - ::group::Pre task execution logs
[2024-05-17T15:21:24.586+0000] {taskinstance.py:2076} INFO - Dependencies all met for dep_context=non-requeueable deps ti=<TaskInstance: process_sales.extract_data_from_api manual__2024-05-17T15:21:08.012127+00:00 [queued]>
[2024-05-17T15:21:24.593+0000] {taskinstance.py:2076} INFO - Dependencies all met for dep_context=requeueable deps ti=<TaskInstance: process_sales.extract_data_from_api manual__2024-05-17T15:21:08.012127+00:00 [queued]>
[2024-05-17T15:21:24.594+0000] {taskinstance.py:2306} INFO - Starting attempt 3 of 3
[2024-05-17T15:21:24.609+0000] {taskinstance.py:2330} INFO - Executing <Task(PythonOperator): extract_data_from_api> on 2024-05-17 15:21:08.012127+00:00
[2024-05-17T15:21:24.621+0000] {warnings.py:110} WARNING - /home/***/.local/lib/python3.12/site-packages/***/task/task_runner/standard_task_runner.py:61: DeprecationWarning: This process (pid=445) is multi-threaded, use of fork() may lead to deadlocks in the child.
  pid = os.fork()

[2024-05-17T15:21:24.623+0000] {standard_task_runner.py:63} INFO - Started process 447 to run task
[2024-05-17T15:21:24.622+0000] {standard_task_runner.py:90} INFO - Running: ['***', 'tasks', 'run', 'process_sales', 'extract_data_from_api', 'manual__2024-05-17T15:21:08.012127+00:00', '--job-id', '193', '--raw', '--subdir', 'DAGS_FOLDER/process_sales.py', '--cfg-path', '/tmp/tmp27w35b3j']
[2024-05-17T15:21:24.627+0000] {standard_task_runner.py:91} INFO - Job 193: Subtask extract_data_from_api
[2024-05-17T15:21:24.681+0000] {task_command.py:426} INFO - Running <TaskInstance: process_sales.extract_data_from_api manual__2024-05-17T15:21:08.012127+00:00 [running]> on host 6239d20906ca
[2024-05-17T15:21:24.763+0000] {taskinstance.py:2648} INFO - Exporting env vars: AIRFLOW_CTX_DAG_EMAIL='ostapenko.vctr@gmail.com' AIRFLOW_CTX_DAG_OWNER='***' AIRFLOW_CTX_DAG_ID='process_sales' AIRFLOW_CTX_TASK_ID='extract_data_from_api' AIRFLOW_CTX_EXECUTION_DATE='2024-05-17T15:21:08.012127+00:00' AIRFLOW_CTX_TRY_NUMBER='3' AIRFLOW_CTX_DAG_RUN_ID='manual__2024-05-17T15:21:08.012127+00:00'
[2024-05-17T15:21:24.770+0000] {taskinstance.py:430} INFO - ::endgroup::
[2024-05-17T15:21:24.772+0000] {taskinstance.py:441} INFO - ::group::Post task execution logs
[2024-05-17T15:21:24.773+0000] {taskinstance.py:2905} ERROR - Task failed with exception
Traceback (most recent call last):
  File "/home/airflow/.local/lib/python3.12/site-packages/airflow/models/taskinstance.py", line 465, in _execute_task
    result = _execute_callable(context=context, **execute_callable_kwargs)
             ^^^^^^^^^^^^^^^^^^^^^^^^^^^^^^^^^^^^^^^^^^^^^^^^^^^^^^^^^^^^^
  File "/home/airflow/.local/lib/python3.12/site-packages/airflow/models/taskinstance.py", line 432, in _execute_callable
    return execute_callable(context=context, **execute_callable_kwargs)
           ^^^^^^^^^^^^^^^^^^^^^^^^^^^^^^^^^^^^^^^^^^^^^^^^^^^^^^^^^^^^
  File "/home/airflow/.local/lib/python3.12/site-packages/airflow/models/baseoperator.py", line 400, in wrapper
    return func(self, *args, **kwargs)
           ^^^^^^^^^^^^^^^^^^^^^^^^^^^
  File "/home/airflow/.local/lib/python3.12/site-packages/airflow/operators/python.py", line 235, in execute
    return_value = self.execute_callable()
                   ^^^^^^^^^^^^^^^^^^^^^^^
  File "/home/airflow/.local/lib/python3.12/site-packages/airflow/operators/python.py", line 252, in execute_callable
    return self.python_callable(*self.op_args, **self.op_kwargs)
           ^^^^^^^^^^^^^^^^^^^^^^^^^^^^^^^^^^^^^^^^^^^^^^^^^^^^^
  File "/opt/airflow/dags/process_sales.py", line 9, in run_job1
    print({{ds}})
            ^^
NameError: name 'ds' is not defined
[2024-05-17T15:21:24.801+0000] {taskinstance.py:1206} INFO - Marking task as FAILED. dag_id=process_sales, task_id=extract_data_from_api, run_id=manual__2024-05-17T15:21:08.012127+00:00, execution_date=20240517T152108, start_date=20240517T152124, end_date=20240517T152124
[2024-05-17T15:21:24.812+0000] {standard_task_runner.py:110} ERROR - Failed to execute job 193 for task extract_data_from_api (name 'ds' is not defined; 447)
[2024-05-17T15:21:24.840+0000] {local_task_job_runner.py:240} INFO - Task exited with return code 1
[2024-05-17T15:21:24.860+0000] {taskinstance.py:3498} INFO - 0 downstream tasks scheduled from follow-on schedule check
[2024-05-17T15:21:24.864+0000] {local_task_job_runner.py:222} INFO - ::endgroup::
